Workbook

Sheet Översikt
B2: 🏠 Husbudget
B3: År: | C3: 2026 | D3: ← byt år här. Översikten räknas automatiskt från fliken Transaktioner.
C5: Inkomster i år | F5: Utgifter i år | I5: Sparat i år | L5: Kvar (ej fördelat)
C6: =SUMIFS(Transaktioner!$E$6:$E$505,Transaktioner!$F$6:$F$505,"Inkomst",Transaktioner!$B$6:$B$505,">="&DATE($C$3,1,1),Transaktioner!$B$6:$B$505,"<"&DATE($C$3+1,1,1)) -> 42000 | F6: =SUMIFS(Transaktioner!$E$6:$E$505,Transaktioner!$F$6:$F$505,"Utgift",Transaktioner!$B$6:$B$505,">="&DATE($C$3,1,1),Transaktioner!$B$6:$B$505,"<"&DATE($C$3+1,1,1)) -> 13740 | I6: =SUMIFS(Transaktioner!$E$6:$E$505,Transaktioner!$F$6:$F$505,"Sparande",Transaktioner!$B$6:$B$505,">="&DATE($C$3,1,1),Transaktioner!$B$6:$B$505,"<"&DATE($C$3+1,1,1)) -> 3000 | L6: =C6-F6-I6 -> 25260
B9: Typ | C9: Kategori | D9: Jan | E9: Feb | F9: Mar | G9: Apr | H9: Maj | I9: Jun | J9: Jul | K9: Aug | L9: Sep | M9: Okt | N9: Nov | O9: Dec | P9: Utfall år | Q9: Budget år | R9: Diff | S9: Förbrukat
B10: =IF(Kategorier!$C$6="","",Kategorier!$B$6) -> Inkomst | C10: =IF(Kategorier!$C$6="","",Kategorier!$C$6) -> Lön | D10: =IF($C10="","",SUMIFS(Transaktioner!$E$6:$E$505,Transaktioner!$C$6:$C$505,$C10,Transaktioner!$B$6:$B$505,">="&DATE($C$3,1,1),Transaktioner!$B$6:$B$505,"<"&DATE($C$3,2,1))) -> 42000 | E10: =IF($C10="","",SUMIFS(Transaktioner!$E$6:$E$505,Transaktioner!$C$6:$C$505,$C10,Transaktioner!$B$6:$B$505,">="&DATE($C$3,2,1),Transaktioner!$B$6:$B$505,"<"&DATE($C$3,3,1))) -> 0 | F10: =IF($C10="","",SUMIFS(Transaktioner!$E$6:$E$505,Transaktioner!$C$6:$C$505,$C10,Transaktioner!$B$6:$B$505,">="&DATE($C$3,3,1),Transaktioner!$B$6:$B$505,"<"&DATE($C$3,4,1))) -> 0 | G10: =IF($C10="","",SUMIFS(Transaktioner!$E$6:$E$505,Transaktioner!$C$6:$C$505,$C10,Transaktioner!$B$6:$B$505,">="&DATE($C$3,4,1),Transaktioner!$B$6:$B$505,"<"&DATE($C$3,5,1))) -> 0 | H10: =IF($C10="","",SUMIFS(Transaktioner!$E$6:$E$505,Transaktioner!$C$6:$C$505,$C10,Transaktioner!$B$6:$B$505,">="&DATE($C$3,5,1),Transaktioner!$B$6:$B$505,"<"&DATE($C$3,6,1))) -> 0 | I10: =IF($C10="","",SUMIFS(Transaktioner!$E$6:$E$505,Transaktioner!$C$6:$C$505,$C10,Transaktioner!$B$6:$B$505,">="&DATE($C$3,6,1),Transaktioner!$B$6:$B$505,"<"&DATE($C$3,7,1))) -> 0 | J10: =IF($C10="","",SUMIFS(Transaktioner!$E$6:$E$505,Transaktioner!$C$6:$C$505,$C10,Transaktioner!$B$6:$B$505,">="&DATE($C$3,7,1),Transaktioner!$B$6:$B$505,"<"&DATE($C$3,8,1))) -> 0 | K10: =IF($C10="","",SUMIFS(Transaktioner!$E$6:$E$505,Transaktioner!$C$6:$C$505,$C10,Transaktioner!$B$6:$B$505,">="&DATE($C$3,8,1),Transaktioner!$B$6:$B$505,"<"&DATE($C$3,9,1))) -> 0 | L10: =IF($C10="","",SUMIFS(Transaktioner!$E$6:$E$505,Transaktioner!$C$6:$C$505,$C10,Transaktioner!$B$6:$B$505,">="&DATE($C$3,9,1),Transaktioner!$B$6:$B$505,"<"&DATE($C$3,10,1))) -> 0 | M10: =IF($C10="","",SUMIFS(Transaktioner!$E$6:$E$505,Transaktioner!$C$6:$C$505,$C10,Transaktioner!$B$6:$B$505,">="&DATE($C$3,10,1),Transaktioner!$B$6:$B$505,"<"&DATE($C$3,11,1))) -> 0 | N10: =IF($C10="","",SUMIFS(Transaktioner!$E$6:$E$505,Transaktioner!$C$6:$C$505,$C10,Transaktioner!$B$6:$B$505,">="&DATE($C$3,11,1),Transaktioner!$B$6:$B$505,"<"&DATE($C$3,12,1))) -> 0 | O10: =IF($C10="","",SUMIFS(Transaktioner!$E$6:$E$505,Transaktioner!$C$6:$C$505,$C10,Transaktioner!$B$6:$B$505,">="&DATE($C$3,12,1),Transaktioner!$B$6:$B$505,"<"&DATE($C$3,13,1))) -> 0 | P10: =IF($C10="","",SUM(D10:O10)) -> 42000 | Q10: =IF($C10="","",Kategorier!$D$6*12) -> 504000 | R10: =IF($C10="","",IF($B10="Inkomst",P10-Q10,Q10-P10)) -> -462000 | S10: =IF(OR($C10="",N(Q10)=0),"",P10/Q10) -> 0.083333333
B11: =IF(Kategorier!$C$7="","",Kategorier!$B$7) -> Inkomst | C11: =IF(Kategorier!$C$7="","",Kategorier!$C$7) -> Barnbidrag | D11: =IF($C11="","",SUMIFS(Transaktioner!$E$6:$E$505,Transaktioner!$C$6:$C$505,$C11,Transaktioner!$B$6:$B$505,">="&DATE($C$3,1,1),Transaktioner!$B$6:$B$505,"<"&DATE($C$3,2,1))) -> 0 | E11: =IF($C11="","",SUMIFS(Transaktioner!$E$6:$E$505,Transaktioner!$C$6:$C$505,$C11,Transaktioner!$B$6:$B$505,">="&DATE($C$3,2,1),Transaktioner!$B$6:$B$505,"<"&DATE($C$3,3,1))) -> 0 | F11: =IF($C11="","",SUMIFS(Transaktioner!$E$6:$E$505,Transaktioner!$C$6:$C$505,$C11,Transaktioner!$B$6:$B$505,">="&DATE($C$3,3,1),Transaktioner!$B$6:$B$505,"<"&DATE($C$3,4,1))) -> 0 | G11: =IF($C11="","",SUMIFS(Transaktioner!$E$6:$E$505,Transaktioner!$C$6:$C$505,$C11,Transaktioner!$B$6:$B$505,">="&DATE($C$3,4,1),Transaktioner!$B$6:$B$505,"<"&DATE($C$3,5,1))) -> 0 | H11: =IF($C11="","",SUMIFS(Transaktioner!$E$6:$E$505,Transaktioner!$C$6:$C$505,$C11,Transaktioner!$B$6:$B$505,">="&DATE($C$3,5,1),Transaktioner!$B$6:$B$505,"<"&DATE($C$3,6,1))) -> 0 | I11: =IF($C11="","",SUMIFS(Transaktioner!$E$6:$E$505,Transaktioner!$C$6:$C$505,$C11,Transaktioner!$B$6:$B$505,">="&DATE($C$3,6,1),Transaktioner!$B$6:$B$505,"<"&DATE($C$3,7,1))) -> 0 | J11: =IF($C11="","",SUMIFS(Transaktioner!$E$6:$E$505,Transaktioner!$C$6:$C$505,$C11,Transaktioner!$B$6:$B$505,">="&DATE($C$3,7,1),Transaktioner!$B$6:$B$505,"<"&DATE($C$3,8,1))) -> 0 | K11: =IF($C11="","",SUMIFS(Transaktioner!$E$6:$E$505,Transaktioner!$C$6:$C$505,$C11,Transaktioner!$B$6:$B$505,">="&DATE($C$3,8,1),Transaktioner!$B$6:$B$505,"<"&DATE($C$3,9,1))) -> 0 | L11: =IF($C11="","",SUMIFS(Transaktioner!$E$6:$E$505,Transaktioner!$C$6:$C$505,$C11,Transaktioner!$B$6:$B$505,">="&DATE($C$3,9,1),Transaktioner!$B$6:$B$505,"<"&DATE($C$3,10,1))) -> 0 | M11: =IF($C11="","",SUMIFS(Transaktioner!$E$6:$E$505,Transaktioner!$C$6:$C$505,$C11,Transaktioner!$B$6:$B$505,">="&DATE($C$3,10,1),Transaktioner!$B$6:$B$505,"<"&DATE($C$3,11,1))) -> 0 | N11: =IF($C11="","",SUMIFS(Transaktioner!$E$6:$E$505,Transaktioner!$C$6:$C$505,$C11,Transaktioner!$B$6:$B$505,">="&DATE($C$3,11,1),Transaktioner!$B$6:$B$505,"<"&DATE($C$3,12,1))) -> 0 | O11: =IF($C11="","",SUMIFS(Transaktioner!$E$6:$E$505,Transaktioner!$C$6:$C$505,$C11,Transaktioner!$B$6:$B$505,">="&DATE($C$3,12,1),Transaktioner!$B$6:$B$505,"<"&DATE($C$3,13,1))) -> 0 | P11: =IF($C11="","",SUM(D11:O11)) -> 0 | Q11: =IF($C11="","",Kategorier!$D$7*12) -> 15000 | R11: =IF($C11="","",IF($B11="Inkomst",P11-Q11,Q11-P11)) -> -15000 | S11: =IF(OR($C11="",N(Q11)=0),"",P11/Q11) -> 0
B12: =IF(Kategorier!$C$8="","",Kategorier!$B$8) -> Inkomst | C12: =IF(Kategorier!$C$8="","",Kategorier!$C$8) -> Övrigt | D12: =IF($C12="","",SUMIFS(Transaktioner!$E$6:$E$505,Transaktioner!$C$6:$C$505,$C12,Transaktioner!$B$6:$B$505,">="&DATE($C$3,1,1),Transaktioner!$B$6:$B$505,"<"&DATE($C$3,2,1))) -> 0 | E12: =IF($C12="","",SUMIFS(Transaktioner!$E$6:$E$505,Transaktioner!$C$6:$C$505,$C12,Transaktioner!$B$6:$B$505,">="&DATE($C$3,2,1),Transaktioner!$B$6:$B$505,"<"&DATE($C$3,3,1))) -> 0 | F12: =IF($C12="","",SUMIFS(Transaktioner!$E$6:$E$505,Transaktioner!$C$6:$C$505,$C12,Transaktioner!$B$6:$B$505,">="&DATE($C$3,3,1),Transaktioner!$B$6:$B$505,"<"&DATE($C$3,4,1))) -> 0 | G12: =IF($C12="","",SUMIFS(Transaktioner!$E$6:$E$505,Transaktioner!$C$6:$C$505,$C12,Transaktioner!$B$6:$B$505,">="&DATE($C$3,4,1),Transaktioner!$B$6:$B$505,"<"&DATE($C$3,5,1))) -> 0 | H12: =IF($C12="","",SUMIFS(Transaktioner!$E$6:$E$505,Transaktioner!$C$6:$C$505,$C12,Transaktioner!$B$6:$B$505,">="&DATE($C$3,5,1),Transaktioner!$B$6:$B$505,"<"&DATE($C$3,6,1))) -> 0 | I12: =IF($C12="","",SUMIFS(Transaktioner!$E$6:$E$505,Transaktioner!$C$6:$C$505,$C12,Transaktioner!$B$6:$B$505,">="&DATE($C$3,6,1),Transaktioner!$B$6:$B$505,"<"&DATE($C$3,7,1))) -> 0 | J12: =IF($C12="","",SUMIFS(Transaktioner!$E$6:$E$505,Transaktioner!$C$6:$C$505,$C12,Transaktioner!$B$6:$B$505,">="&DATE($C$3,7,1),Transaktioner!$B$6:$B$505,"<"&DATE($C$3,8,1))) -> 0 | K12: =IF($C12="","",SUMIFS(Transaktioner!$E$6:$E$505,Transaktioner!$C$6:$C$505,$C12,Transaktioner!$B$6:$B$505,">="&DATE($C$3,8,1),Transaktioner!$B$6:$B$505,"<"&DATE($C$3,9,1))) -> 0 | L12: =IF($C12="","",SUMIFS(Transaktioner!$E$6:$E$505,Transaktioner!$C$6:$C$505,$C12,Transaktioner!$B$6:$B$505,">="&DATE($C$3,9,1),Transaktioner!$B$6:$B$505,"<"&DATE($C$3,10,1))) -> 0 | M12: =IF($C12="","",SUMIFS(Transaktioner!$E$6:$E$505,Transaktioner!$C$6:$C$505,$C12,Transaktioner!$B$6:$B$505,">="&DATE($C$3,10,1),Transaktioner!$B$6:$B$505,"<"&DATE($C$3,11,1))) -> 0 | N12: =IF($C12="","",SUMIFS(Transaktioner!$E$6:$E$505,Transaktioner!$C$6:$C$505,$C12,Transaktioner!$B$6:$B$505,">="&DATE($C$3,11,1),Transaktioner!$B$6:$B$505,"<"&DATE($C$3,12,1))) -> 0 | O12: =IF($C12="","",SUMIFS(Transaktioner!$E$6:$E$505,Transaktioner!$C$6:$C$505,$C12,Transaktioner!$B$6:$B$505,">="&DATE($C$3,12,1),Transaktioner!$B$6:$B$505,"<"&DATE($C$3,13,1))) -> 0 | P12: =IF($C12="","",SUM(D12:O12)) -> 0 | Q12: =IF($C12="","",Kategorier!$D$8*12) -> 0 | R12: =IF($C12="","",IF($B12="Inkomst",P12-Q12,Q12-P12)) -> 0 | S12: =IF(OR($C12="",N(Q12)=0),"",P12/Q12)
B13: =IF(Kategorier!$C$9="","",Kategorier!$B$9) -> Utgift | C13: =IF(Kategorier!$C$9="","",Kategorier!$C$9) -> Boende (hyra/lån) | D13: =IF($C13="","",SUMIFS(Transaktioner!$E$6:$E$505,Transaktioner!$C$6:$C$505,$C13,Transaktioner!$B$6:$B$505,">="&DATE($C$3,1,1),Transaktioner!$B$6:$B$505,"<"&DATE($C$3,2,1))) -> 12500 | E13: =IF($C13="","",SUMIFS(Transaktioner!$E$6:$E$505,Transaktioner!$C$6:$C$505,$C13,Transaktioner!$B$6:$B$505,">="&DATE($C$3,2,1),Transaktioner!$B$6:$B$505,"<"&DATE($C$3,3,1))) -> 0 | F13: =IF($C13="","",SUMIFS(Transaktioner!$E$6:$E$505,Transaktioner!$C$6:$C$505,$C13,Transaktioner!$B$6:$B$505,">="&DATE($C$3,3,1),Transaktioner!$B$6:$B$505,"<"&DATE($C$3,4,1))) -> 0 | G13: =IF($C13="","",SUMIFS(Transaktioner!$E$6:$E$505,Transaktioner!$C$6:$C$505,$C13,Transaktioner!$B$6:$B$505,">="&DATE($C$3,4,1),Transaktioner!$B$6:$B$505,"<"&DATE($C$3,5,1))) -> 0 | H13: =IF($C13="","",SUMIFS(Transaktioner!$E$6:$E$505,Transaktioner!$C$6:$C$505,$C13,Transaktioner!$B$6:$B$505,">="&DATE($C$3,5,1),Transaktioner!$B$6:$B$505,"<"&DATE($C$3,6,1))) -> 0 | I13: =IF($C13="","",SUMIFS(Transaktioner!$E$6:$E$505,Transaktioner!$C$6:$C$505,$C13,Transaktioner!$B$6:$B$505,">="&DATE($C$3,6,1),Transaktioner!$B$6:$B$505,"<"&DATE($C$3,7,1))) -> 0 | J13: =IF($C13="","",SUMIFS(Transaktioner!$E$6:$E$505,Transaktioner!$C$6:$C$505,$C13,Transaktioner!$B$6:$B$505,">="&DATE($C$3,7,1),Transaktioner!$B$6:$B$505,"<"&DATE($C$3,8,1))) -> 0 | K13: =IF($C13="","",SUMIFS(Transaktioner!$E$6:$E$505,Transaktioner!$C$6:$C$505,$C13,Transaktioner!$B$6:$B$505,">="&DATE($C$3,8,1),Transaktioner!$B$6:$B$505,"<"&DATE($C$3,9,1))) -> 0 | L13: =IF($C13="","",SUMIFS(Transaktioner!$E$6:$E$505,Transaktioner!$C$6:$C$505,$C13,Transaktioner!$B$6:$B$505,">="&DATE($C$3,9,1),Transaktioner!$B$6:$B$505,"<"&DATE($C$3,10,1))) -> 0 | M13: =IF($C13="","",SUMIFS(Transaktioner!$E$6:$E$505,Transaktioner!$C$6:$C$505,$C13,Transaktioner!$B$6:$B$505,">="&DATE($C$3,10,1),Transaktioner!$B$6:$B$505,"<"&DATE($C$3,11,1))) -> 0 | N13: =IF($C13="","",SUMIFS(Transaktioner!$E$6:$E$505,Transaktioner!$C$6:$C$505,$C13,Transaktioner!$B$6:$B$505,">="&DATE($C$3,11,1),Transaktioner!$B$6:$B$505,"<"&DATE($C$3,12,1))) -> 0 | O13: =IF($C13="","",SUMIFS(Transaktioner!$E$6:$E$505,Transaktioner!$C$6:$C$505,$C13,Transaktioner!$B$6:$B$505,">="&DATE($C$3,12,1),Transaktioner!$B$6:$B$505,"<"&DATE($C$3,13,1))) -> 0 | P13: =IF($C13="","",SUM(D13:O13)) -> 12500 | Q13: =IF($C13="","",Kategorier!$D$9*12) -> 150000 | R13: =IF($C13="","",IF($B13="Inkomst",P13-Q13,Q13-P13)) -> 137500 | S13: =IF(OR($C13="",N(Q13)=0),"",P13/Q13) -> 0.083333333
B14: =IF(Kategorier!$C$10="","",Kategorier!$B$10) -> Utgift | C14: =IF(Kategorier!$C$10="","",Kategorier!$C$10) -> El & värme | D14: =IF($C14="","",SUMIFS(Transaktioner!$E$6:$E$505,Transaktioner!$C$6:$C$505,$C14,Transaktioner!$B$6:$B$505,">="&DATE($C$3,1,1),Transaktioner!$B$6:$B$505,"<"&DATE($C$3,2,1))) -> 0 | E14: =IF($C14="","",SUMIFS(Transaktioner!$E$6:$E$505,Transaktioner!$C$6:$C$505,$C14,Transaktioner!$B$6:$B$505,">="&DATE($C$3,2,1),Transaktioner!$B$6:$B$505,"<"&DATE($C$3,3,1))) -> 0 | F14: =IF($C14="","",SUMIFS(Transaktioner!$E$6:$E$505,Transaktioner!$C$6:$C$505,$C14,Transaktioner!$B$6:$B$505,">="&DATE($C$3,3,1),Transaktioner!$B$6:$B$505,"<"&DATE($C$3,4,1))) -> 0 | G14: =IF($C14="","",SUMIFS(Transaktioner!$E$6:$E$505,Transaktioner!$C$6:$C$505,$C14,Transaktioner!$B$6:$B$505,">="&DATE($C$3,4,1),Transaktioner!$B$6:$B$505,"<"&DATE($C$3,5,1))) -> 0 | H14: =IF($C14="","",SUMIFS(Transaktioner!$E$6:$E$505,Transaktioner!$C$6:$C$505,$C14,Transaktioner!$B$6:$B$505,">="&DATE($C$3,5,1),Transaktioner!$B$6:$B$505,"<"&DATE($C$3,6,1))) -> 0 | I14: =IF($C14="","",SUMIFS(Transaktioner!$E$6:$E$505,Transaktioner!$C$6:$C$505,$C14,Transaktioner!$B$6:$B$505,">="&DATE($C$3,6,1),Transaktioner!$B$6:$B$505,"<"&DATE($C$3,7,1))) -> 0 | J14: =IF($C14="","",SUMIFS(Transaktioner!$E$6:$E$505,Transaktioner!$C$6:$C$505,$C14,Transaktioner!$B$6:$B$505,">="&DATE($C$3,7,1),Transaktioner!$B$6:$B$505,"<"&DATE($C$3,8,1))) -> 0 | K14: =IF($C14="","",SUMIFS(Transaktioner!$E$6:$E$505,Transaktioner!$C$6:$C$505,$C14,Transaktioner!$B$6:$B$505,">="&DATE($C$3,8,1),Transaktioner!$B$6:$B$505,"<"&DATE($C$3,9,1))) -> 0 | L14: =IF($C14="","",SUMIFS(Transaktioner!$E$6:$E$505,Transaktioner!$C$6:$C$505,$C14,Transaktioner!$B$6:$B$505,">="&DATE($C$3,9,1),Transaktioner!$B$6:$B$505,"<"&DATE($C$3,10,1))) -> 0 | M14: =IF($C14="","",SUMIFS(Transaktioner!$E$6:$E$505,Transaktioner!$C$6:$C$505,$C14,Transaktioner!$B$6:$B$505,">="&DATE($C$3,10,1),Transaktioner!$B$6:$B$505,"<"&DATE($C$3,11,1))) -> 0 | N14: =IF($C14="","",SUMIFS(Transaktioner!$E$6:$E$505,Transaktioner!$C$6:$C$505,$C14,Transaktioner!$B$6:$B$505,">="&DATE($C$3,11,1),Transaktioner!$B$6:$B$505,"<"&DATE($C$3,12,1))) -> 0 | O14: =IF($C14="","",SUMIFS(Transaktioner!$E$6:$E$505,Transaktioner!$C$6:$C$505,$C14,Transaktioner!$B$6:$B$505,">="&DATE($C$3,12,1),Transaktioner!$B$6:$B$505,"<"&DATE($C$3,13,1))) -> 0 | P14: =IF($C14="","",SUM(D14:O14)) -> 0 | Q14: =IF($C14="","",Kategorier!$D$10*12) -> 16800 | R14: =IF($C14="","",IF($B14="Inkomst",P14-Q14,Q14-P14)) -> 16800 | S14: =IF(OR($C14="",N(Q14)=0),"",P14/Q14) -> 0
B15: =IF(Kategorier!$C$11="","",Kategorier!$B$11) -> Utgift | C15: =IF(Kategorier!$C$11="","",Kategorier!$C$11) -> Bredband & mobil | D15: =IF($C15="","",SUMIFS(Transaktioner!$E$6:$E$505,Transaktioner!$C$6:$C$505,$C15,Transaktioner!$B$6:$B$505,">="&DATE($C$3,1,1),Transaktioner!$B$6:$B$505,"<"&DATE($C$3,2,1))) -> 0 | E15: =IF($C15="","",SUMIFS(Transaktioner!$E$6:$E$505,Transaktioner!$C$6:$C$505,$C15,Transaktioner!$B$6:$B$505,">="&DATE($C$3,2,1),Transaktioner!$B$6:$B$505,"<"&DATE($C$3,3,1))) -> 0 | F15: =IF($C15="","",SUMIFS(Transaktioner!$E$6:$E$505,Transaktioner!$C$6:$C$505,$C15,Transaktioner!$B$6:$B$505,">="&DATE($C$3,3,1),Transaktioner!$B$6:$B$505,"<"&DATE($C$3,4,1))) -> 0 | G15: =IF($C15="","",SUMIFS(Transaktioner!$E$6:$E$505,Transaktioner!$C$6:$C$505,$C15,Transaktioner!$B$6:$B$505,">="&DATE($C$3,4,1),Transaktioner!$B$6:$B$505,"<"&DATE($C$3,5,1))) -> 0 | H15: =IF($C15="","",SUMIFS(Transaktioner!$E$6:$E$505,Transaktioner!$C$6:$C$505,$C15,Transaktioner!$B$6:$B$505,">="&DATE($C$3,5,1),Transaktioner!$B$6:$B$505,"<"&DATE($C$3,6,1))) -> 0 | I15: =IF($C15="","",SUMIFS(Transaktioner!$E$6:$E$505,Transaktioner!$C$6:$C$505,$C15,Transaktioner!$B$6:$B$505,">="&DATE($C$3,6,1),Transaktioner!$B$6:$B$505,"<"&DATE($C$3,7,1))) -> 0 | J15: =IF($C15="","",SUMIFS(Transaktioner!$E$6:$E$505,Transaktioner!$C$6:$C$505,$C15,Transaktioner!$B$6:$B$505,">="&DATE($C$3,7,1),Transaktioner!$B$6:$B$505,"<"&DATE($C$3,8,1))) -> 0 | K15: =IF($C15="","",SUMIFS(Transaktioner!$E$6:$E$505,Transaktioner!$C$6:$C$505,$C15,Transaktioner!$B$6:$B$505,">="&DATE($C$3,8,1),Transaktioner!$B$6:$B$505,"<"&DATE($C$3,9,1))) -> 0 | L15: =IF($C15="","",SUMIFS(Transaktioner!$E$6:$E$505,Transaktioner!$C$6:$C$505,$C15,Transaktioner!$B$6:$B$505,">="&DATE($C$3,9,1),Transaktioner!$B$6:$B$505,"<"&DATE($C$3,10,1))) -> 0 | M15: =IF($C15="","",SUMIFS(Transaktioner!$E$6:$E$505,Transaktioner!$C$6:$C$505,$C15,Transaktioner!$B$6:$B$505,">="&DATE($C$3,10,1),Transaktioner!$B$6:$B$505,"<"&DATE($C$3,11,1))) -> 0 | N15: =IF($C15="","",SUMIFS(Transaktioner!$E$6:$E$505,Transaktioner!$C$6:$C$505,$C15,Transaktioner!$B$6:$B$505,">="&DATE($C$3,11,1),Transaktioner!$B$6:$B$505,"<"&DATE($C$3,12,1))) -> 0 | O15: =IF($C15="","",SUMIFS(Transaktioner!$E$6:$E$505,Transaktioner!$C$6:$C$505,$C15,Transaktioner!$B$6:$B$505,">="&DATE($C$3,12,1),Transaktioner!$B$6:$B$505,"<"&DATE($C$3,13,1))) -> 0 | P15: =IF($C15="","",SUM(D15:O15)) -> 0 | Q15: =IF($C15="","",Kategorier!$D$11*12) -> 7800 | R15: =IF($C15="","",IF($B15="Inkomst",P15-Q15,Q15-P15)) -> 7800 | S15: =IF(OR($C15="",N(Q15)=0),"",P15/Q15) -> 0
B16: =IF(Kategorier!$C$12="","",Kategorier!$B$12) -> Utgift | C16: =IF(Kategorier!$C$12="","",Kategorier!$C$12) -> Försäkringar | D16: =IF($C16="","",SUMIFS(Transaktioner!$E$6:$E$505,Transaktioner!$C$6:$C$505,$C16,Transaktioner!$B$6:$B$505,">="&DATE($C$3,1,1),Transaktioner!$B$6:$B$505,"<"&DATE($C$3,2,1))) -> 0 | E16: =IF($C16="","",SUMIFS(Transaktioner!$E$6:$E$505,Transaktioner!$C$6:$C$505,$C16,Transaktioner!$B$6:$B$505,">="&DATE($C$3,2,1),Transaktioner!$B$6:$B$505,"<"&DATE($C$3,3,1))) -> 0 | F16: =IF($C16="","",SUMIFS(Transaktioner!$E$6:$E$505,Transaktioner!$C$6:$C$505,$C16,Transaktioner!$B$6:$B$505,">="&DATE($C$3,3,1),Transaktioner!$B$6:$B$505,"<"&DATE($C$3,4,1))) -> 0 | G16: =IF($C16="","",SUMIFS(Transaktioner!$E$6:$E$505,Transaktioner!$C$6:$C$505,$C16,Transaktioner!$B$6:$B$505,">="&DATE($C$3,4,1),Transaktioner!$B$6:$B$505,"<"&DATE($C$3,5,1))) -> 0 | H16: =IF($C16="","",SUMIFS(Transaktioner!$E$6:$E$505,Transaktioner!$C$6:$C$505,$C16,Transaktioner!$B$6:$B$505,">="&DATE($C$3,5,1),Transaktioner!$B$6:$B$505,"<"&DATE($C$3,6,1))) -> 0 | I16: =IF($C16="","",SUMIFS(Transaktioner!$E$6:$E$505,Transaktioner!$C$6:$C$505,$C16,Transaktioner!$B$6:$B$505,">="&DATE($C$3,6,1),Transaktioner!$B$6:$B$505,"<"&DATE($C$3,7,1))) -> 0 | J16: =IF($C16="","",SUMIFS(Transaktioner!$E$6:$E$505,Transaktioner!$C$6:$C$505,$C16,Transaktioner!$B$6:$B$505,">="&DATE($C$3,7,1),Transaktioner!$B$6:$B$505,"<"&DATE($C$3,8,1))) -> 0 | K16: =IF($C16="","",SUMIFS(Transaktioner!$E$6:$E$505,Transaktioner!$C$6:$C$505,$C16,Transaktioner!$B$6:$B$505,">="&DATE($C$3,8,1),Transaktioner!$B$6:$B$505,"<"&DATE($C$3,9,1))) -> 0 | L16: =IF($C16="","",SUMIFS(Transaktioner!$E$6:$E$505,Transaktioner!$C$6:$C$505,$C16,Transaktioner!$B$6:$B$505,">="&DATE($C$3,9,1),Transaktioner!$B$6:$B$505,"<"&DATE($C$3,10,1))) -> 0 | M16: =IF($C16="","",SUMIFS(Transaktioner!$E$6:$E$505,Transaktioner!$C$6:$C$505,$C16,Transaktioner!$B$6:$B$505,">="&DATE($C$3,10,1),Transaktioner!$B$6:$B$505,"<"&DATE($C$3,11,1))) -> 0 | N16: =IF($C16="","",SUMIFS(Transaktioner!$E$6:$E$505,Transaktioner!$C$6:$C$505,$C16,Transaktioner!$B$6:$B$505,">="&DATE($C$3,11,1),Transaktioner!$B$6:$B$505,"<"&DATE($C$3,12,1))) -> 0 | O16: =IF($C16="","",SUMIFS(Transaktioner!$E$6:$E$505,Transaktioner!$C$6:$C$505,$C16,Transaktioner!$B$6:$B$505,">="&DATE($C$3,12,1),Transaktioner!$B$6:$B$505,"<"&DATE($C$3,13,1))) -> 0 | P16: =IF($C16="","",SUM(D16:O16)) -> 0 | Q16: =IF($C16="","",Kategorier!$D$12*12) -> 10800 | R16: =IF($C16="","",IF($B16="Inkomst",P16-Q16,Q16-P16)) -> 10800 | S16: =IF(OR($C16="",N(Q16)=0),"",P16/Q16) -> 0
B17: =IF(Kategorier!$C$13="","",Kategorier!$B$13) -> Utgift | C17: =IF(Kategorier!$C$13="","",Kategorier!$C$13) -> Mat & hushåll | D17: =IF($C17="","",SUMIFS(Transaktioner!$E$6:$E$505,Transaktioner!$C$6:$C$505,$C17,Transaktioner!$B$6:$B$505,">="&DATE($C$3,1,1),Transaktioner!$B$6:$B$505,"<"&DATE($C$3,2,1))) -> 1240 | E17: =IF($C17="","",SUMIFS(Transaktioner!$E$6:$E$505,Transaktioner!$C$6:$C$505,$C17,Transaktioner!$B$6:$B$505,">="&DATE($C$3,2,1),Transaktioner!$B$6:$B$505,"<"&DATE($C$3,3,1))) -> 0 | F17: =IF($C17="","",SUMIFS(Transaktioner!$E$6:$E$505,Transaktioner!$C$6:$C$505,$C17,Transaktioner!$B$6:$B$505,">="&DATE($C$3,3,1),Transaktioner!$B$6:$B$505,"<"&DATE($C$3,4,1))) -> 0 | G17: =IF($C17="","",SUMIFS(Transaktioner!$E$6:$E$505,Transaktioner!$C$6:$C$505,$C17,Transaktioner!$B$6:$B$505,">="&DATE($C$3,4,1),Transaktioner!$B$6:$B$505,"<"&DATE($C$3,5,1))) -> 0 | H17: =IF($C17="","",SUMIFS(Transaktioner!$E$6:$E$505,Transaktioner!$C$6:$C$505,$C17,Transaktioner!$B$6:$B$505,">="&DATE($C$3,5,1),Transaktioner!$B$6:$B$505,"<"&DATE($C$3,6,1))) -> 0 | I17: =IF($C17="","",SUMIFS(Transaktioner!$E$6:$E$505,Transaktioner!$C$6:$C$505,$C17,Transaktioner!$B$6:$B$505,">="&DATE($C$3,6,1),Transaktioner!$B$6:$B$505,"<"&DATE($C$3,7,1))) -> 0 | J17: =IF($C17="","",SUMIFS(Transaktioner!$E$6:$E$505,Transaktioner!$C$6:$C$505,$C17,Transaktioner!$B$6:$B$505,">="&DATE($C$3,7,1),Transaktioner!$B$6:$B$505,"<"&DATE($C$3,8,1))) -> 0 | K17: =IF($C17="","",SUMIFS(Transaktioner!$E$6:$E$505,Transaktioner!$C$6:$C$505,$C17,Transaktioner!$B$6:$B$505,">="&DATE($C$3,8,1),Transaktioner!$B$6:$B$505,"<"&DATE($C$3,9,1))) -> 0 | L17: =IF($C17="","",SUMIFS(Transaktioner!$E$6:$E$505,Transaktioner!$C$6:$C$505,$C17,Transaktioner!$B$6:$B$505,">="&DATE($C$3,9,1),Transaktioner!$B$6:$B$505,"<"&DATE($C$3,10,1))) -> 0 | M17: =IF($C17="","",SUMIFS(Transaktioner!$E$6:$E$505,Transaktioner!$C$6:$C$505,$C17,Transaktioner!$B$6:$B$505,">="&DATE($C$3,10,1),Transaktioner!$B$6:$B$505,"<"&DATE($C$3,11,1))) -> 0 | N17: =IF($C17="","",SUMIFS(Transaktioner!$E$6:$E$505,Transaktioner!$C$6:$C$505,$C17,Transaktioner!$B$6:$B$505,">="&DATE($C$3,11,1),Transaktioner!$B$6:$B$505,"<"&DATE($C$3,12,1))) -> 0 | O17: =IF($C17="","",SUMIFS(Transaktioner!$E$6:$E$505,Transaktioner!$C$6:$C$505,$C17,Transaktioner!$B$6:$B$505,">="&DATE($C$3,12,1),Transaktioner!$B$6:$B$505,"<"&DATE($C$3,13,1))) -> 0 | P17: =IF($C17="","",SUM(D17:O17)) -> 1240 | Q17: =IF($C17="","",Kategorier!$D$13*12) -> 90000 | R17: =IF($C17="","",IF($B17="Inkomst",P17-Q17,Q17-P17)) -> 88760 | S17: =IF(OR($C17="",N(Q17)=0),"",P17/Q17) -> 0.013777778
B18: =IF(Kategorier!$C$14="","",Kategorier!$B$14) -> Utgift | C18: =IF(Kategorier!$C$14="","",Kategorier!$C$14) -> Transport | D18: =IF($C18="","",SUMIFS(Transaktioner!$E$6:$E$505,Transaktioner!$C$6:$C$505,$C18,Transaktioner!$B$6:$B$505,">="&DATE($C$3,1,1),Transaktioner!$B$6:$B$505,"<"&DATE($C$3,2,1))) -> 0 | E18: =IF($C18="","",SUMIFS(Transaktioner!$E$6:$E$505,Transaktioner!$C$6:$C$505,$C18,Transaktioner!$B$6:$B$505,">="&DATE($C$3,2,1),Transaktioner!$B$6:$B$505,"<"&DATE($C$3,3,1))) -> 0 | F18: =IF($C18="","",SUMIFS(Transaktioner!$E$6:$E$505,Transaktioner!$C$6:$C$505,$C18,Transaktioner!$B$6:$B$505,">="&DATE($C$3,3,1),Transaktioner!$B$6:$B$505,"<"&DATE($C$3,4,1))) -> 0 | G18: =IF($C18="","",SUMIFS(Transaktioner!$E$6:$E$505,Transaktioner!$C$6:$C$505,$C18,Transaktioner!$B$6:$B$505,">="&DATE($C$3,4,1),Transaktioner!$B$6:$B$505,"<"&DATE($C$3,5,1))) -> 0 | H18: =IF($C18="","",SUMIFS(Transaktioner!$E$6:$E$505,Transaktioner!$C$6:$C$505,$C18,Transaktioner!$B$6:$B$505,">="&DATE($C$3,5,1),Transaktioner!$B$6:$B$505,"<"&DATE($C$3,6,1))) -> 0 | I18: =IF($C18="","",SUMIFS(Transaktioner!$E$6:$E$505,Transaktioner!$C$6:$C$505,$C18,Transaktioner!$B$6:$B$505,">="&DATE($C$3,6,1),Transaktioner!$B$6:$B$505,"<"&DATE($C$3,7,1))) -> 0 | J18: =IF($C18="","",SUMIFS(Transaktioner!$E$6:$E$505,Transaktioner!$C$6:$C$505,$C18,Transaktioner!$B$6:$B$505,">="&DATE($C$3,7,1),Transaktioner!$B$6:$B$505,"<"&DATE($C$3,8,1))) -> 0 | K18: =IF($C18="","",SUMIFS(Transaktioner!$E$6:$E$505,Transaktioner!$C$6:$C$505,$C18,Transaktioner!$B$6:$B$505,">="&DATE($C$3,8,1),Transaktioner!$B$6:$B$505,"<"&DATE($C$3,9,1))) -> 0 | L18: =IF($C18="","",SUMIFS(Transaktioner!$E$6:$E$505,Transaktioner!$C$6:$C$505,$C18,Transaktioner!$B$6:$B$505,">="&DATE($C$3,9,1),Transaktioner!$B$6:$B$505,"<"&DATE($C$3,10,1))) -> 0 | M18: =IF($C18="","",SUMIFS(Transaktioner!$E$6:$E$505,Transaktioner!$C$6:$C$505,$C18,Transaktioner!$B$6:$B$505,">="&DATE($C$3,10,1),Transaktioner!$B$6:$B$505,"<"&DATE($C$3,11,1))) -> 0 | N18: =IF($C18="","",SUMIFS(Transaktioner!$E$6:$E$505,Transaktioner!$C$6:$C$505,$C18,Transaktioner!$B$6:$B$505,">="&DATE($C$3,11,1),Transaktioner!$B$6:$B$505,"<"&DATE($C$3,12,1))) -> 0 | O18: =IF($C18="","",SUMIFS(Transaktioner!$E$6:$E$505,Transaktioner!$C$6:$C$505,$C18,Transaktioner!$B$6:$B$505,">="&DATE($C$3,12,1),Transaktioner!$B$6:$B$505,"<"&DATE($C$3,13,1))) -> 0 | P18: =IF($C18="","",SUM(D18:O18)) -> 0 | Q18: =IF($C18="","",Kategorier!$D$14*12) -> 30000 | R18: =IF($C18="","",IF($B18="Inkomst",P18-Q18,Q18-P18)) -> 30000 | S18: =IF(OR($C18="",N(Q18)=0),"",P18/Q18) -> 0
B19: =IF(Kategorier!$C$15="","",Kategorier!$B$15) -> Utgift | C19: =IF(Kategorier!$C$15="","",Kategorier!$C$15) -> Barn | D19: =IF($C19="","",SUMIFS(Transaktioner!$E$6:$E$505,Transaktioner!$C$6:$C$505,$C19,Transaktioner!$B$6:$B$505,">="&DATE($C$3,1,1),Transaktioner!$B$6:$B$505,"<"&DATE($C$3,2,1))) -> 0 | E19: =IF($C19="","",SUMIFS(Transaktioner!$E$6:$E$505,Transaktioner!$C$6:$C$505,$C19,Transaktioner!$B$6:$B$505,">="&DATE($C$3,2,1),Transaktioner!$B$6:$B$505,"<"&DATE($C$3,3,1))) -> 0 | F19: =IF($C19="","",SUMIFS(Transaktioner!$E$6:$E$505,Transaktioner!$C$6:$C$505,$C19,Transaktioner!$B$6:$B$505,">="&DATE($C$3,3,1),Transaktioner!$B$6:$B$505,"<"&DATE($C$3,4,1))) -> 0 | G19: =IF($C19="","",SUMIFS(Transaktioner!$E$6:$E$505,Transaktioner!$C$6:$C$505,$C19,Transaktioner!$B$6:$B$505,">="&DATE($C$3,4,1),Transaktioner!$B$6:$B$505,"<"&DATE($C$3,5,1))) -> 0 | H19: =IF($C19="","",SUMIFS(Transaktioner!$E$6:$E$505,Transaktioner!$C$6:$C$505,$C19,Transaktioner!$B$6:$B$505,">="&DATE($C$3,5,1),Transaktioner!$B$6:$B$505,"<"&DATE($C$3,6,1))) -> 0 | I19: =IF($C19="","",SUMIFS(Transaktioner!$E$6:$E$505,Transaktioner!$C$6:$C$505,$C19,Transaktioner!$B$6:$B$505,">="&DATE($C$3,6,1),Transaktioner!$B$6:$B$505,"<"&DATE($C$3,7,1))) -> 0 | J19: =IF($C19="","",SUMIFS(Transaktioner!$E$6:$E$505,Transaktioner!$C$6:$C$505,$C19,Transaktioner!$B$6:$B$505,">="&DATE($C$3,7,1),Transaktioner!$B$6:$B$505,"<"&DATE($C$3,8,1))) -> 0 | K19: =IF($C19="","",SUMIFS(Transaktioner!$E$6:$E$505,Transaktioner!$C$6:$C$505,$C19,Transaktioner!$B$6:$B$505,">="&DATE($C$3,8,1),Transaktioner!$B$6:$B$505,"<"&DATE($C$3,9,1))) -> 0 | L19: =IF($C19="","",SUMIFS(Transaktioner!$E$6:$E$505,Transaktioner!$C$6:$C$505,$C19,Transaktioner!$B$6:$B$505,">="&DATE($C$3,9,1),Transaktioner!$B$6:$B$505,"<"&DATE($C$3,10,1))) -> 0 | M19: =IF($C19="","",SUMIFS(Transaktioner!$E$6:$E$505,Transaktioner!$C$6:$C$505,$C19,Transaktioner!$B$6:$B$505,">="&DATE($C$3,10,1),Transaktioner!$B$6:$B$505,"<"&DATE($C$3,11,1))) -> 0 | N19: =IF($C19="","",SUMIFS(Transaktioner!$E$6:$E$505,Transaktioner!$C$6:$C$505,$C19,Transaktioner!$B$6:$B$505,">="&DATE($C$3,11,1),Transaktioner!$B$6:$B$505,"<"&DATE($C$3,12,1))) -> 0 | O19: =IF($C19="","",SUMIFS(Transaktioner!$E$6:$E$505,Transaktioner!$C$6:$C$505,$C19,Transaktioner!$B$6:$B$505,">="&DATE($C$3,12,1),Transaktioner!$B$6:$B$505,"<"&DATE($C$3,13,1))) -> 0 | P19: =IF($C19="","",SUM(D19:O19)) -> 0 | Q19: =IF($C19="","",Kategorier!$D$15*12) -> 18000 | R19: =IF($C19="","",IF($B19="Inkomst",P19-Q19,Q19-P19)) -> 18000 | S19: =IF(OR($C19="",N(Q19)=0),"",P19/Q19) -> 0
B20: =IF(Kategorier!$C$16="","",Kategorier!$B$16) -> Utgift | C20: =IF(Kategorier!$C$16="","",Kategorier!$C$16) -> Hälsa & träning | D20: =IF($C20="","",SUMIFS(Transaktioner!$E$6:$E$505,Transaktioner!$C$6:$C$505,$C20,Transaktioner!$B$6:$B$505,">="&DATE($C$3,1,1),Transaktioner!$B$6:$B$505,"<"&DATE($C$3,2,1))) -> 0 | E20: =IF($C20="","",SUMIFS(Transaktioner!$E$6:$E$505,Transaktioner!$C$6:$C$505,$C20,Transaktioner!$B$6:$B$505,">="&DATE($C$3,2,1),Transaktioner!$B$6:$B$505,"<"&DATE($C$3,3,1))) -> 0 | F20: =IF($C20="","",SUMIFS(Transaktioner!$E$6:$E$505,Transaktioner!$C$6:$C$505,$C20,Transaktioner!$B$6:$B$505,">="&DATE($C$3,3,1),Transaktioner!$B$6:$B$505,"<"&DATE($C$3,4,1))) -> 0 | G20: =IF($C20="","",SUMIFS(Transaktioner!$E$6:$E$505,Transaktioner!$C$6:$C$505,$C20,Transaktioner!$B$6:$B$505,">="&DATE($C$3,4,1),Transaktioner!$B$6:$B$505,"<"&DATE($C$3,5,1))) -> 0 | H20: =IF($C20="","",SUMIFS(Transaktioner!$E$6:$E$505,Transaktioner!$C$6:$C$505,$C20,Transaktioner!$B$6:$B$505,">="&DATE($C$3,5,1),Transaktioner!$B$6:$B$505,"<"&DATE($C$3,6,1))) -> 0 | I20: =IF($C20="","",SUMIFS(Transaktioner!$E$6:$E$505,Transaktioner!$C$6:$C$505,$C20,Transaktioner!$B$6:$B$505,">="&DATE($C$3,6,1),Transaktioner!$B$6:$B$505,"<"&DATE($C$3,7,1))) -> 0 | J20: =IF($C20="","",SUMIFS(Transaktioner!$E$6:$E$505,Transaktioner!$C$6:$C$505,$C20,Transaktioner!$B$6:$B$505,">="&DATE($C$3,7,1),Transaktioner!$B$6:$B$505,"<"&DATE($C$3,8,1))) -> 0 | K20: =IF($C20="","",SUMIFS(Transaktioner!$E$6:$E$505,Transaktioner!$C$6:$C$505,$C20,Transaktioner!$B$6:$B$505,">="&DATE($C$3,8,1),Transaktioner!$B$6:$B$505,"<"&DATE($C$3,9,1))) -> 0 | L20: =IF($C20="","",SUMIFS(Transaktioner!$E$6:$E$505,Transaktioner!$C$6:$C$505,$C20,Transaktioner!$B$6:$B$505,">="&DATE($C$3,9,1),Transaktioner!$B$6:$B$505,"<"&DATE($C$3,10,1))) -> 0 | M20: =IF($C20="","",SUMIFS(Transaktioner!$E$6:$E$505,Transaktioner!$C$6:$C$505,$C20,Transaktioner!$B$6:$B$505,">="&DATE($C$3,10,1),Transaktioner!$B$6:$B$505,"<"&DATE($C$3,11,1))) -> 0 | N20: =IF($C20="","",SUMIFS(Transaktioner!$E$6:$E$505,Transaktioner!$C$6:$C$505,$C20,Transaktioner!$B$6:$B$505,">="&DATE($C$3,11,1),Transaktioner!$B$6:$B$505,"<"&DATE($C$3,12,1))) -> 0 | O20: =IF($C20="","",SUMIFS(Transaktioner!$E$6:$E$505,Transaktioner!$C$6:$C$505,$C20,Transaktioner!$B$6:$B$505,">="&DATE($C$3,12,1),Transaktioner!$B$6:$B$505,"<"&DATE($C$3,13,1))) -> 0 | P20: =IF($C20="","",SUM(D20:O20)) -> 0 | Q20: =IF($C20="","",Kategorier!$D$16*12) -> 7200 | R20: =IF($C20="","",IF($B20="Inkomst",P20-Q20,Q20-P20)) -> 7200 | S20: =IF(OR($C20="",N(Q20)=0),"",P20/Q20) -> 0
B21: =IF(Kategorier!$C$17="","",Kategorier!$B$17) -> Utgift | C21: =IF(Kategorier!$C$17="","",Kategorier!$C$17) -> Nöje & restaurang | D21: =IF($C21="","",SUMIFS(Transaktioner!$E$6:$E$505,Transaktioner!$C$6:$C$505,$C21,Transaktioner!$B$6:$B$505,">="&DATE($C$3,1,1),Transaktioner!$B$6:$B$505,"<"&DATE($C$3,2,1))) -> 0 | E21: =IF($C21="","",SUMIFS(Transaktioner!$E$6:$E$505,Transaktioner!$C$6:$C$505,$C21,Transaktioner!$B$6:$B$505,">="&DATE($C$3,2,1),Transaktioner!$B$6:$B$505,"<"&DATE($C$3,3,1))) -> 0 | F21: =IF($C21="","",SUMIFS(Transaktioner!$E$6:$E$505,Transaktioner!$C$6:$C$505,$C21,Transaktioner!$B$6:$B$505,">="&DATE($C$3,3,1),Transaktioner!$B$6:$B$505,"<"&DATE($C$3,4,1))) -> 0 | G21: =IF($C21="","",SUMIFS(Transaktioner!$E$6:$E$505,Transaktioner!$C$6:$C$505,$C21,Transaktioner!$B$6:$B$505,">="&DATE($C$3,4,1),Transaktioner!$B$6:$B$505,"<"&DATE($C$3,5,1))) -> 0 | H21: =IF($C21="","",SUMIFS(Transaktioner!$E$6:$E$505,Transaktioner!$C$6:$C$505,$C21,Transaktioner!$B$6:$B$505,">="&DATE($C$3,5,1),Transaktioner!$B$6:$B$505,"<"&DATE($C$3,6,1))) -> 0 | I21: =IF($C21="","",SUMIFS(Transaktioner!$E$6:$E$505,Transaktioner!$C$6:$C$505,$C21,Transaktioner!$B$6:$B$505,">="&DATE($C$3,6,1),Transaktioner!$B$6:$B$505,"<"&DATE($C$3,7,1))) -> 0 | J21: =IF($C21="","",SUMIFS(Transaktioner!$E$6:$E$505,Transaktioner!$C$6:$C$505,$C21,Transaktioner!$B$6:$B$505,">="&DATE($C$3,7,1),Transaktioner!$B$6:$B$505,"<"&DATE($C$3,8,1))) -> 0 | K21: =IF($C21="","",SUMIFS(Transaktioner!$E$6:$E$505,Transaktioner!$C$6:$C$505,$C21,Transaktioner!$B$6:$B$505,">="&DATE($C$3,8,1),Transaktioner!$B$6:$B$505,"<"&DATE($C$3,9,1))) -> 0 | L21: =IF($C21="","",SUMIFS(Transaktioner!$E$6:$E$505,Transaktioner!$C$6:$C$505,$C21,Transaktioner!$B$6:$B$505,">="&DATE($C$3,9,1),Transaktioner!$B$6:$B$505,"<"&DATE($C$3,10,1))) -> 0 | M21: =IF($C21="","",SUMIFS(Transaktioner!$E$6:$E$505,Transaktioner!$C$6:$C$505,$C21,Transaktioner!$B$6:$B$505,">="&DATE($C$3,10,1),Transaktioner!$B$6:$B$505,"<"&DATE($C$3,11,1))) -> 0 | N21: =IF($C21="","",SUMIFS(Transaktioner!$E$6:$E$505,Transaktioner!$C$6:$C$505,$C21,Transaktioner!$B$6:$B$505,">="&DATE($C$3,11,1),Transaktioner!$B$6:$B$505,"<"&DATE($C$3,12,1))) -> 0 | O21: =IF($C21="","",SUMIFS(Transaktioner!$E$6:$E$505,Transaktioner!$C$6:$C$505,$C21,Transaktioner!$B$6:$B$505,">="&DATE($C$3,12,1),Transaktioner!$B$6:$B$505,"<"&DATE($C$3,13,1))) -> 0 | P21: =IF($C21="","",SUM(D21:O21)) -> 0 | Q21: =IF($C21="","",Kategorier!$D$17*12) -> 24000 | R21: =IF($C21="","",IF($B21="Inkomst",P21-Q21,Q21-P21)) -> 24000 | S21: =IF(OR($C21="",N(Q21)=0),"",P21/Q21) -> 0
B22: =IF(Kategorier!$C$18="","",Kategorier!$B$18) -> Utgift | C22: =IF(Kategorier!$C$18="","",Kategorier!$C$18) -> Kläder | D22: =IF($C22="","",SUMIFS(Transaktioner!$E$6:$E$505,Transaktioner!$C$6:$C$505,$C22,Transaktioner!$B$6:$B$505,">="&DATE($C$3,1,1),Transaktioner!$B$6:$B$505,"<"&DATE($C$3,2,1))) -> 0 | E22: =IF($C22="","",SUMIFS(Transaktioner!$E$6:$E$505,Transaktioner!$C$6:$C$505,$C22,Transaktioner!$B$6:$B$505,">="&DATE($C$3,2,1),Transaktioner!$B$6:$B$505,"<"&DATE($C$3,3,1))) -> 0 | F22: =IF($C22="","",SUMIFS(Transaktioner!$E$6:$E$505,Transaktioner!$C$6:$C$505,$C22,Transaktioner!$B$6:$B$505,">="&DATE($C$3,3,1),Transaktioner!$B$6:$B$505,"<"&DATE($C$3,4,1))) -> 0 | G22: =IF($C22="","",SUMIFS(Transaktioner!$E$6:$E$505,Transaktioner!$C$6:$C$505,$C22,Transaktioner!$B$6:$B$505,">="&DATE($C$3,4,1),Transaktioner!$B$6:$B$505,"<"&DATE($C$3,5,1))) -> 0 | H22: =IF($C22="","",SUMIFS(Transaktioner!$E$6:$E$505,Transaktioner!$C$6:$C$505,$C22,Transaktioner!$B$6:$B$505,">="&DATE($C$3,5,1),Transaktioner!$B$6:$B$505,"<"&DATE($C$3,6,1))) -> 0 | I22: =IF($C22="","",SUMIFS(Transaktioner!$E$6:$E$505,Transaktioner!$C$6:$C$505,$C22,Transaktioner!$B$6:$B$505,">="&DATE($C$3,6,1),Transaktioner!$B$6:$B$505,"<"&DATE($C$3,7,1))) -> 0 | J22: =IF($C22="","",SUMIFS(Transaktioner!$E$6:$E$505,Transaktioner!$C$6:$C$505,$C22,Transaktioner!$B$6:$B$505,">="&DATE($C$3,7,1),Transaktioner!$B$6:$B$505,"<"&DATE($C$3,8,1))) -> 0 | K22: =IF($C22="","",SUMIFS(Transaktioner!$E$6:$E$505,Transaktioner!$C$6:$C$505,$C22,Transaktioner!$B$6:$B$505,">="&DATE($C$3,8,1),Transaktioner!$B$6:$B$505,"<"&DATE($C$3,9,1))) -> 0 | L22: =IF($C22="","",SUMIFS(Transaktioner!$E$6:$E$505,Transaktioner!$C$6:$C$505,$C22,Transaktioner!$B$6:$B$505,">="&DATE($C$3,9,1),Transaktioner!$B$6:$B$505,"<"&DATE($C$3,10,1))) -> 0 | M22: =IF($C22="","",SUMIFS(Transaktioner!$E$6:$E$505,Transaktioner!$C$6:$C$505,$C22,Transaktioner!$B$6:$B$505,">="&DATE($C$3,10,1),Transaktioner!$B$6:$B$505,"<"&DATE($C$3,11,1))) -> 0 | N22: =IF($C22="","",SUMIFS(Transaktioner!$E$6:$E$505,Transaktioner!$C$6:$C$505,$C22,Transaktioner!$B$6:$B$505,">="&DATE($C$3,11,1),Transaktioner!$B$6:$B$505,"<"&DATE($C$3,12,1))) -> 0 | O22: =IF($C22="","",SUMIFS(Transaktioner!$E$6:$E$505,Transaktioner!$C$6:$C$505,$C22,Transaktioner!$B$6:$B$505,">="&DATE($C$3,12,1),Transaktioner!$B$6:$B$505,"<"&DATE($C$3,13,1))) -> 0 | P22: =IF($C22="","",SUM(D22:O22)) -> 0 | Q22: =IF($C22="","",Kategorier!$D$18*12) -> 12000 | R22: =IF($C22="","",IF($B22="Inkomst",P22-Q22,Q22-P22)) -> 12000 | S22: =IF(OR($C22="",N(Q22)=0),"",P22/Q22) -> 0
B23: =IF(Kategorier!$C$19="","",Kategorier!$B$19) -> Utgift | C23: =IF(Kategorier!$C$19="","",Kategorier!$C$19) -> Prenumerationer | D23: =IF($C23="","",SUMIFS(Transaktioner!$E$6:$E$505,Transaktioner!$C$6:$C$505,$C23,Transaktioner!$B$6:$B$505,">="&DATE($C$3,1,1),Transaktioner!$B$6:$B$505,"<"&DATE($C$3,2,1))) -> 0 | E23: =IF($C23="","",SUMIFS(Transaktioner!$E$6:$E$505,Transaktioner!$C$6:$C$505,$C23,Transaktioner!$B$6:$B$505,">="&DATE($C$3,2,1),Transaktioner!$B$6:$B$505,"<"&DATE($C$3,3,1))) -> 0 | F23: =IF($C23="","",SUMIFS(Transaktioner!$E$6:$E$505,Transaktioner!$C$6:$C$505,$C23,Transaktioner!$B$6:$B$505,">="&DATE($C$3,3,1),Transaktioner!$B$6:$B$505,"<"&DATE($C$3,4,1))) -> 0 | G23: =IF($C23="","",SUMIFS(Transaktioner!$E$6:$E$505,Transaktioner!$C$6:$C$505,$C23,Transaktioner!$B$6:$B$505,">="&DATE($C$3,4,1),Transaktioner!$B$6:$B$505,"<"&DATE($C$3,5,1))) -> 0 | H23: =IF($C23="","",SUMIFS(Transaktioner!$E$6:$E$505,Transaktioner!$C$6:$C$505,$C23,Transaktioner!$B$6:$B$505,">="&DATE($C$3,5,1),Transaktioner!$B$6:$B$505,"<"&DATE($C$3,6,1))) -> 0 | I23: =IF($C23="","",SUMIFS(Transaktioner!$E$6:$E$505,Transaktioner!$C$6:$C$505,$C23,Transaktioner!$B$6:$B$505,">="&DATE($C$3,6,1),Transaktioner!$B$6:$B$505,"<"&DATE($C$3,7,1))) -> 0 | J23: =IF($C23="","",SUMIFS(Transaktioner!$E$6:$E$505,Transaktioner!$C$6:$C$505,$C23,Transaktioner!$B$6:$B$505,">="&DATE($C$3,7,1),Transaktioner!$B$6:$B$505,"<"&DATE($C$3,8,1))) -> 0 | K23: =IF($C23="","",SUMIFS(Transaktioner!$E$6:$E$505,Transaktioner!$C$6:$C$505,$C23,Transaktioner!$B$6:$B$505,">="&DATE($C$3,8,1),Transaktioner!$B$6:$B$505,"<"&DATE($C$3,9,1))) -> 0 | L23: =IF($C23="","",SUMIFS(Transaktioner!$E$6:$E$505,Transaktioner!$C$6:$C$505,$C23,Transaktioner!$B$6:$B$505,">="&DATE($C$3,9,1),Transaktioner!$B$6:$B$505,"<"&DATE($C$3,10,1))) -> 0 | M23: =IF($C23="","",SUMIFS(Transaktioner!$E$6:$E$505,Transaktioner!$C$6:$C$505,$C23,Transaktioner!$B$6:$B$505,">="&DATE($C$3,10,1),Transaktioner!$B$6:$B$505,"<"&DATE($C$3,11,1))) -> 0 | N23: =IF($C23="","",SUMIFS(Transaktioner!$E$6:$E$505,Transaktioner!$C$6:$C$505,$C23,Transaktioner!$B$6:$B$505,">="&DATE($C$3,11,1),Transaktioner!$B$6:$B$505,"<"&DATE($C$3,12,1))) -> 0 | O23: =IF($C23="","",SUMIFS(Transaktioner!$E$6:$E$505,Transaktioner!$C$6:$C$505,$C23,Transaktioner!$B$6:$B$505,">="&DATE($C$3,12,1),Transaktioner!$B$6:$B$505,"<"&DATE($C$3,13,1))) -> 0 | P23: =IF($C23="","",SUM(D23:O23)) -> 0 | Q23: =IF($C23="","",Kategorier!$D$19*12) -> 4800 | R23: =IF($C23="","",IF($B23="Inkomst",P23-Q23,Q23-P23)) -> 4800 | S23: =IF(OR($C23="",N(Q23)=0),"",P23/Q23) -> 0
B24: =IF(Kategorier!$C$20="","",Kategorier!$B$20) -> Utgift | C24: =IF(Kategorier!$C$20="","",Kategorier!$C$20) -> Övrigt | D24: =IF($C24="","",SUMIFS(Transaktioner!$E$6:$E$505,Transaktioner!$C$6:$C$505,$C24,Transaktioner!$B$6:$B$505,">="&DATE($C$3,1,1),Transaktioner!$B$6:$B$505,"<"&DATE($C$3,2,1))) -> 0 | E24: =IF($C24="","",SUMIFS(Transaktioner!$E$6:$E$505,Transaktioner!$C$6:$C$505,$C24,Transaktioner!$B$6:$B$505,">="&DATE($C$3,2,1),Transaktioner!$B$6:$B$505,"<"&DATE($C$3,3,1))) -> 0 | F24: =IF($C24="","",SUMIFS(Transaktioner!$E$6:$E$505,Transaktioner!$C$6:$C$505,$C24,Transaktioner!$B$6:$B$505,">="&DATE($C$3,3,1),Transaktioner!$B$6:$B$505,"<"&DATE($C$3,4,1))) -> 0 | G24: =IF($C24="","",SUMIFS(Transaktioner!$E$6:$E$505,Transaktioner!$C$6:$C$505,$C24,Transaktioner!$B$6:$B$505,">="&DATE($C$3,4,1),Transaktioner!$B$6:$B$505,"<"&DATE($C$3,5,1))) -> 0 | H24: =IF($C24="","",SUMIFS(Transaktioner!$E$6:$E$505,Transaktioner!$C$6:$C$505,$C24,Transaktioner!$B$6:$B$505,">="&DATE($C$3,5,1),Transaktioner!$B$6:$B$505,"<"&DATE($C$3,6,1))) -> 0 | I24: =IF($C24="","",SUMIFS(Transaktioner!$E$6:$E$505,Transaktioner!$C$6:$C$505,$C24,Transaktioner!$B$6:$B$505,">="&DATE($C$3,6,1),Transaktioner!$B$6:$B$505,"<"&DATE($C$3,7,1))) -> 0 | J24: =IF($C24="","",SUMIFS(Transaktioner!$E$6:$E$505,Transaktioner!$C$6:$C$505,$C24,Transaktioner!$B$6:$B$505,">="&DATE($C$3,7,1),Transaktioner!$B$6:$B$505,"<"&DATE($C$3,8,1))) -> 0 | K24: =IF($C24="","",SUMIFS(Transaktioner!$E$6:$E$505,Transaktioner!$C$6:$C$505,$C24,Transaktioner!$B$6:$B$505,">="&DATE($C$3,8,1),Transaktioner!$B$6:$B$505,"<"&DATE($C$3,9,1))) -> 0 | L24: =IF($C24="","",SUMIFS(Transaktioner!$E$6:$E$505,Transaktioner!$C$6:$C$505,$C24,Transaktioner!$B$6:$B$505,">="&DATE($C$3,9,1),Transaktioner!$B$6:$B$505,"<"&DATE($C$3,10,1))) -> 0 | M24: =IF($C24="","",SUMIFS(Transaktioner!$E$6:$E$505,Transaktioner!$C$6:$C$505,$C24,Transaktioner!$B$6:$B$505,">="&DATE($C$3,10,1),Transaktioner!$B$6:$B$505,"<"&DATE($C$3,11,1))) -> 0 | N24: =IF($C24="","",SUMIFS(Transaktioner!$E$6:$E$505,Transaktioner!$C$6:$C$505,$C24,Transaktioner!$B$6:$B$505,">="&DATE($C$3,11,1),Transaktioner!$B$6:$B$505,"<"&DATE($C$3,12,1))) -> 0 | O24: =IF($C24="","",SUMIFS(Transaktioner!$E$6:$E$505,Transaktioner!$C$6:$C$505,$C24,Transaktioner!$B$6:$B$505,">="&DATE($C$3,12,1),Transaktioner!$B$6:$B$505,"<"&DATE($C$3,13,1))) -> 0 | P24: =IF($C24="","",SUM(D24:O24)) -> 0 | Q24: =IF($C24="","",Kategorier!$D$20*12) -> 12000 | R24: =IF($C24="","",IF($B24="Inkomst",P24-Q24,Q24-P24)) -> 12000 | S24: =IF(OR($C24="",N(Q24)=0),"",P24/Q24) -> 0
B25: =IF(Kategorier!$C$21="","",Kategorier!$B$21) -> Sparande | C25: =IF(Kategorier!$C$21="","",Kategorier!$C$21) -> Buffert | D25: =IF($C25="","",SUMIFS(Transaktioner!$E$6:$E$505,Transaktioner!$C$6:$C$505,$C25,Transaktioner!$B$6:$B$505,">="&DATE($C$3,1,1),Transaktioner!$B$6:$B$505,"<"&DATE($C$3,2,1))) -> 3000 | E25: =IF($C25="","",SUMIFS(Transaktioner!$E$6:$E$505,Transaktioner!$C$6:$C$505,$C25,Transaktioner!$B$6:$B$505,">="&DATE($C$3,2,1),Transaktioner!$B$6:$B$505,"<"&DATE($C$3,3,1))) -> 0 | F25: =IF($C25="","",SUMIFS(Transaktioner!$E$6:$E$505,Transaktioner!$C$6:$C$505,$C25,Transaktioner!$B$6:$B$505,">="&DATE($C$3,3,1),Transaktioner!$B$6:$B$505,"<"&DATE($C$3,4,1))) -> 0 | G25: =IF($C25="","",SUMIFS(Transaktioner!$E$6:$E$505,Transaktioner!$C$6:$C$505,$C25,Transaktioner!$B$6:$B$505,">="&DATE($C$3,4,1),Transaktioner!$B$6:$B$505,"<"&DATE($C$3,5,1))) -> 0 | H25: =IF($C25="","",SUMIFS(Transaktioner!$E$6:$E$505,Transaktioner!$C$6:$C$505,$C25,Transaktioner!$B$6:$B$505,">="&DATE($C$3,5,1),Transaktioner!$B$6:$B$505,"<"&DATE($C$3,6,1))) -> 0 | I25: =IF($C25="","",SUMIFS(Transaktioner!$E$6:$E$505,Transaktioner!$C$6:$C$505,$C25,Transaktioner!$B$6:$B$505,">="&DATE($C$3,6,1),Transaktioner!$B$6:$B$505,"<"&DATE($C$3,7,1))) -> 0 | J25: =IF($C25="","",SUMIFS(Transaktioner!$E$6:$E$505,Transaktioner!$C$6:$C$505,$C25,Transaktioner!$B$6:$B$505,">="&DATE($C$3,7,1),Transaktioner!$B$6:$B$505,"<"&DATE($C$3,8,1))) -> 0 | K25: =IF($C25="","",SUMIFS(Transaktioner!$E$6:$E$505,Transaktioner!$C$6:$C$505,$C25,Transaktioner!$B$6:$B$505,">="&DATE($C$3,8,1),Transaktioner!$B$6:$B$505,"<"&DATE($C$3,9,1))) -> 0 | L25: =IF($C25="","",SUMIFS(Transaktioner!$E$6:$E$505,Transaktioner!$C$6:$C$505,$C25,Transaktioner!$B$6:$B$505,">="&DATE($C$3,9,1),Transaktioner!$B$6:$B$505,"<"&DATE($C$3,10,1))) -> 0 | M25: =IF($C25="","",SUMIFS(Transaktioner!$E$6:$E$505,Transaktioner!$C$6:$C$505,$C25,Transaktioner!$B$6:$B$505,">="&DATE($C$3,10,1),Transaktioner!$B$6:$B$505,"<"&DATE($C$3,11,1))) -> 0 | N25: =IF($C25="","",SUMIFS(Transaktioner!$E$6:$E$505,Transaktioner!$C$6:$C$505,$C25,Transaktioner!$B$6:$B$505,">="&DATE($C$3,11,1),Transaktioner!$B$6:$B$505,"<"&DATE($C$3,12,1))) -> 0 | O25: =IF($C25="","",SUMIFS(Transaktioner!$E$6:$E$505,Transaktioner!$C$6:$C$505,$C25,Transaktioner!$B$6:$B$505,">="&DATE($C$3,12,1),Transaktioner!$B$6:$B$505,"<"&DATE($C$3,13,1))) -> 0 | P25: =IF($C25="","",SUM(D25:O25)) -> 3000 | Q25: =IF($C25="","",Kategorier!$D$21*12) -> 36000 | R25: =IF($C25="","",IF($B25="Inkomst",P25-Q25,Q25-P25)) -> 33000 | S25: =IF(OR($C25="",N(Q25)=0),"",P25/Q25) -> 0.083333333
B26: =IF(Kategorier!$C$22="","",Kategorier!$B$22) -> Sparande | C26: =IF(Kategorier!$C$22="","",Kategorier!$C$22) -> Fonder | D26: =IF($C26="","",SUMIFS(Transaktioner!$E$6:$E$505,Transaktioner!$C$6:$C$505,$C26,Transaktioner!$B$6:$B$505,">="&DATE($C$3,1,1),Transaktioner!$B$6:$B$505,"<"&DATE($C$3,2,1))) -> 0 | E26: =IF($C26="","",SUMIFS(Transaktioner!$E$6:$E$505,Transaktioner!$C$6:$C$505,$C26,Transaktioner!$B$6:$B$505,">="&DATE($C$3,2,1),Transaktioner!$B$6:$B$505,"<"&DATE($C$3,3,1))) -> 0 | F26: =IF($C26="","",SUMIFS(Transaktioner!$E$6:$E$505,Transaktioner!$C$6:$C$505,$C26,Transaktioner!$B$6:$B$505,">="&DATE($C$3,3,1),Transaktioner!$B$6:$B$505,"<"&DATE($C$3,4,1))) -> 0 | G26: =IF($C26="","",SUMIFS(Transaktioner!$E$6:$E$505,Transaktioner!$C$6:$C$505,$C26,Transaktioner!$B$6:$B$505,">="&DATE($C$3,4,1),Transaktioner!$B$6:$B$505,"<"&DATE($C$3,5,1))) -> 0 | H26: =IF($C26="","",SUMIFS(Transaktioner!$E$6:$E$505,Transaktioner!$C$6:$C$505,$C26,Transaktioner!$B$6:$B$505,">="&DATE($C$3,5,1),Transaktioner!$B$6:$B$505,"<"&DATE($C$3,6,1))) -> 0 | I26: =IF($C26="","",SUMIFS(Transaktioner!$E$6:$E$505,Transaktioner!$C$6:$C$505,$C26,Transaktioner!$B$6:$B$505,">="&DATE($C$3,6,1),Transaktioner!$B$6:$B$505,"<"&DATE($C$3,7,1))) -> 0 | J26: =IF($C26="","",SUMIFS(Transaktioner!$E$6:$E$505,Transaktioner!$C$6:$C$505,$C26,Transaktioner!$B$6:$B$505,">="&DATE($C$3,7,1),Transaktioner!$B$6:$B$505,"<"&DATE($C$3,8,1))) -> 0 | K26: =IF($C26="","",SUMIFS(Transaktioner!$E$6:$E$505,Transaktioner!$C$6:$C$505,$C26,Transaktioner!$B$6:$B$505,">="&DATE($C$3,8,1),Transaktioner!$B$6:$B$505,"<"&DATE($C$3,9,1))) -> 0 | L26: =IF($C26="","",SUMIFS(Transaktioner!$E$6:$E$505,Transaktioner!$C$6:$C$505,$C26,Transaktioner!$B$6:$B$505,">="&DATE($C$3,9,1),Transaktioner!$B$6:$B$505,"<"&DATE($C$3,10,1))) -> 0 | M26: =IF($C26="","",SUMIFS(Transaktioner!$E$6:$E$505,Transaktioner!$C$6:$C$505,$C26,Transaktioner!$B$6:$B$505,">="&DATE($C$3,10,1),Transaktioner!$B$6:$B$505,"<"&DATE($C$3,11,1))) -> 0 | N26: =IF($C26="","",SUMIFS(Transaktioner!$E$6:$E$505,Transaktioner!$C$6:$C$505,$C26,Transaktioner!$B$6:$B$505,">="&DATE($C$3,11,1),Transaktioner!$B$6:$B$505,"<"&DATE($C$3,12,1))) -> 0 | O26: =IF($C26="","",SUMIFS(Transaktioner!$E$6:$E$505,Transaktioner!$C$6:$C$505,$C26,Transaktioner!$B$6:$B$505,">="&DATE($C$3,12,1),Transaktioner!$B$6:$B$505,"<"&DATE($C$3,13,1))) -> 0 | P26: =IF($C26="","",SUM(D26:O26)) -> 0 | Q26: =IF($C26="","",Kategorier!$D$22*12) -> 30000 | R26: =IF($C26="","",IF($B26="Inkomst",P26-Q26,Q26-P26)) -> 30000 | S26: =IF(OR($C26="",N(Q26)=0),"",P26/Q26) -> 0
B27: =IF(Kategorier!$C$23="","",Kategorier!$B$23) | C27: =IF(Kategorier!$C$23="","",Kategorier!$C$23) | D27: =IF($C27="","",SUMIFS(Transaktioner!$E$6:$E$505,Transaktioner!$C$6:$C$505,$C27,Transaktioner!$B$6:$B$505,">="&DATE($C$3,1,1),Transaktioner!$B$6:$B$505,"<"&DATE($C$3,2,1))) | E27: =IF($C27="","",SUMIFS(Transaktioner!$E$6:$E$505,Transaktioner!$C$6:$C$505,$C27,Transaktioner!$B$6:$B$505,">="&DATE($C$3,2,1),Transaktioner!$B$6:$B$505,"<"&DATE($C$3,3,1))) | F27: =IF($C27="","",SUMIFS(Transaktioner!$E$6:$E$505,Transaktioner!$C$6:$C$505,$C27,Transaktioner!$B$6:$B$505,">="&DATE($C$3,3,1),Transaktioner!$B$6:$B$505,"<"&DATE($C$3,4,1))) | G27: =IF($C27="","",SUMIFS(Transaktioner!$E$6:$E$505,Transaktioner!$C$6:$C$505,$C27,Transaktioner!$B$6:$B$505,">="&DATE($C$3,4,1),Transaktioner!$B$6:$B$505,"<"&DATE($C$3,5,1))) | H27: =IF($C27="","",SUMIFS(Transaktioner!$E$6:$E$505,Transaktioner!$C$6:$C$505,$C27,Transaktioner!$B$6:$B$505,">="&DATE($C$3,5,1),Transaktioner!$B$6:$B$505,"<"&DATE($C$3,6,1))) | I27: =IF($C27="","",SUMIFS(Transaktioner!$E$6:$E$505,Transaktioner!$C$6:$C$505,$C27,Transaktioner!$B$6:$B$505,">="&DATE($C$3,6,1),Transaktioner!$B$6:$B$505,"<"&DATE($C$3,7,1))) | J27: =IF($C27="","",SUMIFS(Transaktioner!$E$6:$E$505,Transaktioner!$C$6:$C$505,$C27,Transaktioner!$B$6:$B$505,">="&DATE($C$3,7,1),Transaktioner!$B$6:$B$505,"<"&DATE($C$3,8,1))) | K27: =IF($C27="","",SUMIFS(Transaktioner!$E$6:$E$505,Transaktioner!$C$6:$C$505,$C27,Transaktioner!$B$6:$B$505,">="&DATE($C$3,8,1),Transaktioner!$B$6:$B$505,"<"&DATE($C$3,9,1))) | L27: =IF($C27="","",SUMIFS(Transaktioner!$E$6:$E$505,Transaktioner!$C$6:$C$505,$C27,Transaktioner!$B$6:$B$505,">="&DATE($C$3,9,1),Transaktioner!$B$6:$B$505,"<"&DATE($C$3,10,1))) | M27: =IF($C27="","",SUMIFS(Transaktioner!$E$6:$E$505,Transaktioner!$C$6:$C$505,$C27,Transaktioner!$B$6:$B$505,">="&DATE($C$3,10,1),Transaktioner!$B$6:$B$505,"<"&DATE($C$3,11,1))) | N27: =IF($C27="","",SUMIFS(Transaktioner!$E$6:$E$505,Transaktioner!$C$6:$C$505,$C27,Transaktioner!$B$6:$B$505,">="&DATE($C$3,11,1),Transaktioner!$B$6:$B$505,"<"&DATE($C$3,12,1))) | O27: =IF($C27="","",SUMIFS(Transaktioner!$E$6:$E$505,Transaktioner!$C$6:$C$505,$C27,Transaktioner!$B$6:$B$505,">="&DATE($C$3,12,1),Transaktioner!$B$6:$B$505,"<"&DATE($C$3,13,1))) | P27: =IF($C27="","",SUM(D27:O27)) | Q27: =IF($C27="","",Kategorier!$D$23*12) | R27: =IF($C27="","",IF($B27="Inkomst",P27-Q27,Q27-P27)) | S27: =IF(OR($C27="",N(Q27)=0),"",P27/Q27)
B28: =IF(Kategorier!$C$24="","",Kategorier!$B$24) | C28: =IF(Kategorier!$C$24="","",Kategorier!$C$24) | D28: =IF($C28="","",SUMIFS(Transaktioner!$E$6:$E$505,Transaktioner!$C$6:$C$505,$C28,Transaktioner!$B$6:$B$505,">="&DATE($C$3,1,1),Transaktioner!$B$6:$B$505,"<"&DATE($C$3,2,1))) | E28: =IF($C28="","",SUMIFS(Transaktioner!$E$6:$E$505,Transaktioner!$C$6:$C$505,$C28,Transaktioner!$B$6:$B$505,">="&DATE($C$3,2,1),Transaktioner!$B$6:$B$505,"<"&DATE($C$3,3,1))) | F28: =IF($C28="","",SUMIFS(Transaktioner!$E$6:$E$505,Transaktioner!$C$6:$C$505,$C28,Transaktioner!$B$6:$B$505,">="&DATE($C$3,3,1),Transaktioner!$B$6:$B$505,"<"&DATE($C$3,4,1))) | G28: =IF($C28="","",SUMIFS(Transaktioner!$E$6:$E$505,Transaktioner!$C$6:$C$505,$C28,Transaktioner!$B$6:$B$505,">="&DATE($C$3,4,1),Transaktioner!$B$6:$B$505,"<"&DATE($C$3,5,1))) | H28: =IF($C28="","",SUMIFS(Transaktioner!$E$6:$E$505,Transaktioner!$C$6:$C$505,$C28,Transaktioner!$B$6:$B$505,">="&DATE($C$3,5,1),Transaktioner!$B$6:$B$505,"<"&DATE($C$3,6,1))) | I28: =IF($C28="","",SUMIFS(Transaktioner!$E$6:$E$505,Transaktioner!$C$6:$C$505,$C28,Transaktioner!$B$6:$B$505,">="&DATE($C$3,6,1),Transaktioner!$B$6:$B$505,"<"&DATE($C$3,7,1))) | J28: =IF($C28="","",SUMIFS(Transaktioner!$E$6:$E$505,Transaktioner!$C$6:$C$505,$C28,Transaktioner!$B$6:$B$505,">="&DATE($C$3,7,1),Transaktioner!$B$6:$B$505,"<"&DATE($C$3,8,1))) | K28: =IF($C28="","",SUMIFS(Transaktioner!$E$6:$E$505,Transaktioner!$C$6:$C$505,$C28,Transaktioner!$B$6:$B$505,">="&DATE($C$3,8,1),Transaktioner!$B$6:$B$505,"<"&DATE($C$3,9,1))) | L28: =IF($C28="","",SUMIFS(Transaktioner!$E$6:$E$505,Transaktioner!$C$6:$C$505,$C28,Transaktioner!$B$6:$B$505,">="&DATE($C$3,9,1),Transaktioner!$B$6:$B$505,"<"&DATE($C$3,10,1))) | M28: =IF($C28="","",SUMIFS(Transaktioner!$E$6:$E$505,Transaktioner!$C$6:$C$505,$C28,Transaktioner!$B$6:$B$505,">="&DATE($C$3,10,1),Transaktioner!$B$6:$B$505,"<"&DATE($C$3,11,1))) | N28: =IF($C28="","",SUMIFS(Transaktioner!$E$6:$E$505,Transaktioner!$C$6:$C$505,$C28,Transaktioner!$B$6:$B$505,">="&DATE($C$3,11,1),Transaktioner!$B$6:$B$505,"<"&DATE($C$3,12,1))) | O28: =IF($C28="","",SUMIFS(Transaktioner!$E$6:$E$505,Transaktioner!$C$6:$C$505,$C28,Transaktioner!$B$6:$B$505,">="&DATE($C$3,12,1),Transaktioner!$B$6:$B$505,"<"&DATE($C$3,13,1))) | P28: =IF($C28="","",SUM(D28:O28)) | Q28: =IF($C28="","",Kategorier!$D$24*12) | R28: =IF($C28="","",IF($B28="Inkomst",P28-Q28,Q28-P28)) | S28: =IF(OR($C28="",N(Q28)=0),"",P28/Q28)
B29: =IF(Kategorier!$C$25="","",Kategorier!$B$25) | C29: =IF(Kategorier!$C$25="","",Kategorier!$C$25) | D29: =IF($C29="","",SUMIFS(Transaktioner!$E$6:$E$505,Transaktioner!$C$6:$C$505,$C29,Transaktioner!$B$6:$B$505,">="&DATE($C$3,1,1),Transaktioner!$B$6:$B$505,"<"&DATE($C$3,2,1))) | E29: =IF($C29="","",SUMIFS(Transaktioner!$E$6:$E$505,Transaktioner!$C$6:$C$505,$C29,Transaktioner!$B$6:$B$505,">="&DATE($C$3,2,1),Transaktioner!$B$6:$B$505,"<"&DATE($C$3,3,1))) | F29: =IF($C29="","",SUMIFS(Transaktioner!$E$6:$E$505,Transaktioner!$C$6:$C$505,$C29,Transaktioner!$B$6:$B$505,">="&DATE($C$3,3,1),Transaktioner!$B$6:$B$505,"<"&DATE($C$3,4,1))) | G29: =IF($C29="","",SUMIFS(Transaktioner!$E$6:$E$505,Transaktioner!$C$6:$C$505,$C29,Transaktioner!$B$6:$B$505,">="&DATE($C$3,4,1),Transaktioner!$B$6:$B$505,"<"&DATE($C$3,5,1))) | H29: =IF($C29="","",SUMIFS(Transaktioner!$E$6:$E$505,Transaktioner!$C$6:$C$505,$C29,Transaktioner!$B$6:$B$505,">="&DATE($C$3,5,1),Transaktioner!$B$6:$B$505,"<"&DATE($C$3,6,1))) | I29: =IF($C29="","",SUMIFS(Transaktioner!$E$6:$E$505,Transaktioner!$C$6:$C$505,$C29,Transaktioner!$B$6:$B$505,">="&DATE($C$3,6,1),Transaktioner!$B$6:$B$505,"<"&DATE($C$3,7,1))) | J29: =IF($C29="","",SUMIFS(Transaktioner!$E$6:$E$505,Transaktioner!$C$6:$C$505,$C29,Transaktioner!$B$6:$B$505,">="&DATE($C$3,7,1),Transaktioner!$B$6:$B$505,"<"&DATE($C$3,8,1))) | K29: =IF($C29="","",SUMIFS(Transaktioner!$E$6:$E$505,Transaktioner!$C$6:$C$505,$C29,Transaktioner!$B$6:$B$505,">="&DATE($C$3,8,1),Transaktioner!$B$6:$B$505,"<"&DATE($C$3,9,1))) | L29: =IF($C29="","",SUMIFS(Transaktioner!$E$6:$E$505,Transaktioner!$C$6:$C$505,$C29,Transaktioner!$B$6:$B$505,">="&DATE($C$3,9,1),Transaktioner!$B$6:$B$505,"<"&DATE($C$3,10,1))) | M29: =IF($C29="","",SUMIFS(Transaktioner!$E$6:$E$505,Transaktioner!$C$6:$C$505,$C29,Transaktioner!$B$6:$B$505,">="&DATE($C$3,10,1),Transaktioner!$B$6:$B$505,"<"&DATE($C$3,11,1))) | N29: =IF($C29="","",SUMIFS(Transaktioner!$E$6:$E$505,Transaktioner!$C$6:$C$505,$C29,Transaktioner!$B$6:$B$505,">="&DATE($C$3,11,1),Transaktioner!$B$6:$B$505,"<"&DATE($C$3,12,1))) | O29: =IF($C29="","",SUMIFS(Transaktioner!$E$6:$E$505,Transaktioner!$C$6:$C$505,$C29,Transaktioner!$B$6:$B$505,">="&DATE($C$3,12,1),Transaktioner!$B$6:$B$505,"<"&DATE($C$3,13,1))) | P29: =IF($C29="","",SUM(D29:O29)) | Q29: =IF($C29="","",Kategorier!$D$25*12) | R29: =IF($C29="","",IF($B29="Inkomst",P29-Q29,Q29-P29)) | S29: =IF(OR($C29="",N(Q29)=0),"",P29/Q29)
B30: =IF(Kategorier!$C$26="","",Kategorier!$B$26) | C30: =IF(Kategorier!$C$26="","",Kategorier!$C$26) | D30: =IF($C30="","",SUMIFS(Transaktioner!$E$6:$E$505,Transaktioner!$C$6:$C$505,$C30,Transaktioner!$B$6:$B$505,">="&DATE($C$3,1,1),Transaktioner!$B$6:$B$505,"<"&DATE($C$3,2,1))) | E30: =IF($C30="","",SUMIFS(Transaktioner!$E$6:$E$505,Transaktioner!$C$6:$C$505,$C30,Transaktioner!$B$6:$B$505,">="&DATE($C$3,2,1),Transaktioner!$B$6:$B$505,"<"&DATE($C$3,3,1))) | F30: =IF($C30="","",SUMIFS(Transaktioner!$E$6:$E$505,Transaktioner!$C$6:$C$505,$C30,Transaktioner!$B$6:$B$505,">="&DATE($C$3,3,1),Transaktioner!$B$6:$B$505,"<"&DATE($C$3,4,1))) | G30: =IF($C30="","",SUMIFS(Transaktioner!$E$6:$E$505,Transaktioner!$C$6:$C$505,$C30,Transaktioner!$B$6:$B$505,">="&DATE($C$3,4,1),Transaktioner!$B$6:$B$505,"<"&DATE($C$3,5,1))) | H30: =IF($C30="","",SUMIFS(Transaktioner!$E$6:$E$505,Transaktioner!$C$6:$C$505,$C30,Transaktioner!$B$6:$B$505,">="&DATE($C$3,5,1),Transaktioner!$B$6:$B$505,"<"&DATE($C$3,6,1))) | I30: =IF($C30="","",SUMIFS(Transaktioner!$E$6:$E$505,Transaktioner!$C$6:$C$505,$C30,Transaktioner!$B$6:$B$505,">="&DATE($C$3,6,1),Transaktioner!$B$6:$B$505,"<"&DATE($C$3,7,1))) | J30: =IF($C30="","",SUMIFS(Transaktioner!$E$6:$E$505,Transaktioner!$C$6:$C$505,$C30,Transaktioner!$B$6:$B$505,">="&DATE($C$3,7,1),Transaktioner!$B$6:$B$505,"<"&DATE($C$3,8,1))) | K30: =IF($C30="","",SUMIFS(Transaktioner!$E$6:$E$505,Transaktioner!$C$6:$C$505,$C30,Transaktioner!$B$6:$B$505,">="&DATE($C$3,8,1),Transaktioner!$B$6:$B$505,"<"&DATE($C$3,9,1))) | L30: =IF($C30="","",SUMIFS(Transaktioner!$E$6:$E$505,Transaktioner!$C$6:$C$505,$C30,Transaktioner!$B$6:$B$505,">="&DATE($C$3,9,1),Transaktioner!$B$6:$B$505,"<"&DATE($C$3,10,1))) | M30: =IF($C30="","",SUMIFS(Transaktioner!$E$6:$E$505,Transaktioner!$C$6:$C$505,$C30,Transaktioner!$B$6:$B$505,">="&DATE($C$3,10,1),Transaktioner!$B$6:$B$505,"<"&DATE($C$3,11,1))) | N30: =IF($C30="","",SUMIFS(Transaktioner!$E$6:$E$505,Transaktioner!$C$6:$C$505,$C30,Transaktioner!$B$6:$B$505,">="&DATE($C$3,11,1),Transaktioner!$B$6:$B$505,"<"&DATE($C$3,12,1))) | O30: =IF($C30="","",SUMIFS(Transaktioner!$E$6:$E$505,Transaktioner!$C$6:$C$505,$C30,Transaktioner!$B$6:$B$505,">="&DATE($C$3,12,1),Transaktioner!$B$6:$B$505,"<"&DATE($C$3,13,1))) | P30: =IF($C30="","",SUM(D30:O30)) | Q30: =IF($C30="","",Kategorier!$D$26*12) | R30: =IF($C30="","",IF($B30="Inkomst",P30-Q30,Q30-P30)) | S30: =IF(OR($C30="",N(Q30)=0),"",P30/Q30)
B31: =IF(Kategorier!$C$27="","",Kategorier!$B$27) | C31: =IF(Kategorier!$C$27="","",Kategorier!$C$27) | D31: =IF($C31="","",SUMIFS(Transaktioner!$E$6:$E$505,Transaktioner!$C$6:$C$505,$C31,Transaktioner!$B$6:$B$505,">="&DATE($C$3,1,1),Transaktioner!$B$6:$B$505,"<"&DATE($C$3,2,1))) | E31: =IF($C31="","",SUMIFS(Transaktioner!$E$6:$E$505,Transaktioner!$C$6:$C$505,$C31,Transaktioner!$B$6:$B$505,">="&DATE($C$3,2,1),Transaktioner!$B$6:$B$505,"<"&DATE($C$3,3,1))) | F31: =IF($C31="","",SUMIFS(Transaktioner!$E$6:$E$505,Transaktioner!$C$6:$C$505,$C31,Transaktioner!$B$6:$B$505,">="&DATE($C$3,3,1),Transaktioner!$B$6:$B$505,"<"&DATE($C$3,4,1))) | G31: =IF($C31="","",SUMIFS(Transaktioner!$E$6:$E$505,Transaktioner!$C$6:$C$505,$C31,Transaktioner!$B$6:$B$505,">="&DATE($C$3,4,1),Transaktioner!$B$6:$B$505,"<"&DATE($C$3,5,1))) | H31: =IF($C31="","",SUMIFS(Transaktioner!$E$6:$E$505,Transaktioner!$C$6:$C$505,$C31,Transaktioner!$B$6:$B$505,">="&DATE($C$3,5,1),Transaktioner!$B$6:$B$505,"<"&DATE($C$3,6,1))) | I31: =IF($C31="","",SUMIFS(Transaktioner!$E$6:$E$505,Transaktioner!$C$6:$C$505,$C31,Transaktioner!$B$6:$B$505,">="&DATE($C$3,6,1),Transaktioner!$B$6:$B$505,"<"&DATE($C$3,7,1))) | J31: =IF($C31="","",SUMIFS(Transaktioner!$E$6:$E$505,Transaktioner!$C$6:$C$505,$C31,Transaktioner!$B$6:$B$505,">="&DATE($C$3,7,1),Transaktioner!$B$6:$B$505,"<"&DATE($C$3,8,1))) | K31: =IF($C31="","",SUMIFS(Transaktioner!$E$6:$E$505,Transaktioner!$C$6:$C$505,$C31,Transaktioner!$B$6:$B$505,">="&DATE($C$3,8,1),Transaktioner!$B$6:$B$505,"<"&DATE($C$3,9,1))) | L31: =IF($C31="","",SUMIFS(Transaktioner!$E$6:$E$505,Transaktioner!$C$6:$C$505,$C31,Transaktioner!$B$6:$B$505,">="&DATE($C$3,9,1),Transaktioner!$B$6:$B$505,"<"&DATE($C$3,10,1))) | M31: =IF($C31="","",SUMIFS(Transaktioner!$E$6:$E$505,Transaktioner!$C$6:$C$505,$C31,Transaktioner!$B$6:$B$505,">="&DATE($C$3,10,1),Transaktioner!$B$6:$B$505,"<"&DATE($C$3,11,1))) | N31: =IF($C31="","",SUMIFS(Transaktioner!$E$6:$E$505,Transaktioner!$C$6:$C$505,$C31,Transaktioner!$B$6:$B$505,">="&DATE($C$3,11,1),Transaktioner!$B$6:$B$505,"<"&DATE($C$3,12,1))) | O31: =IF($C31="","",SUMIFS(Transaktioner!$E$6:$E$505,Transaktioner!$C$6:$C$505,$C31,Transaktioner!$B$6:$B$505,">="&DATE($C$3,12,1),Transaktioner!$B$6:$B$505,"<"&DATE($C$3,13,1))) | P31: =IF($C31="","",SUM(D31:O31)) | Q31: =IF($C31="","",Kategorier!$D$27*12) | R31: =IF($C31="","",IF($B31="Inkomst",P31-Q31,Q31-P31)) | S31: =IF(OR($C31="",N(Q31)=0),"",P31/Q31)
B32: =IF(Kategorier!$C$28="","",Kategorier!$B$28) | C32: =IF(Kategorier!$C$28="","",Kategorier!$C$28) | D32: =IF($C32="","",SUMIFS(Transaktioner!$E$6:$E$505,Transaktioner!$C$6:$C$505,$C32,Transaktioner!$B$6:$B$505,">="&DATE($C$3,1,1),Transaktioner!$B$6:$B$505,"<"&DATE($C$3,2,1))) | E32: =IF($C32="","",SUMIFS(Transaktioner!$E$6:$E$505,Transaktioner!$C$6:$C$505,$C32,Transaktioner!$B$6:$B$505,">="&DATE($C$3,2,1),Transaktioner!$B$6:$B$505,"<"&DATE($C$3,3,1))) | F32: =IF($C32="","",SUMIFS(Transaktioner!$E$6:$E$505,Transaktioner!$C$6:$C$505,$C32,Transaktioner!$B$6:$B$505,">="&DATE($C$3,3,1),Transaktioner!$B$6:$B$505,"<"&DATE($C$3,4,1))) | G32: =IF($C32="","",SUMIFS(Transaktioner!$E$6:$E$505,Transaktioner!$C$6:$C$505,$C32,Transaktioner!$B$6:$B$505,">="&DATE($C$3,4,1),Transaktioner!$B$6:$B$505,"<"&DATE($C$3,5,1))) | H32: =IF($C32="","",SUMIFS(Transaktioner!$E$6:$E$505,Transaktioner!$C$6:$C$505,$C32,Transaktioner!$B$6:$B$505,">="&DATE($C$3,5,1),Transaktioner!$B$6:$B$505,"<"&DATE($C$3,6,1))) | I32: =IF($C32="","",SUMIFS(Transaktioner!$E$6:$E$505,Transaktioner!$C$6:$C$505,$C32,Transaktioner!$B$6:$B$505,">="&DATE($C$3,6,1),Transaktioner!$B$6:$B$505,"<"&DATE($C$3,7,1))) | J32: =IF($C32="","",SUMIFS(Transaktioner!$E$6:$E$505,Transaktioner!$C$6:$C$505,$C32,Transaktioner!$B$6:$B$505,">="&DATE($C$3,7,1),Transaktioner!$B$6:$B$505,"<"&DATE($C$3,8,1))) | K32: =IF($C32="","",SUMIFS(Transaktioner!$E$6:$E$505,Transaktioner!$C$6:$C$505,$C32,Transaktioner!$B$6:$B$505,">="&DATE($C$3,8,1),Transaktioner!$B$6:$B$505,"<"&DATE($C$3,9,1))) | L32: =IF($C32="","",SUMIFS(Transaktioner!$E$6:$E$505,Transaktioner!$C$6:$C$505,$C32,Transaktioner!$B$6:$B$505,">="&DATE($C$3,9,1),Transaktioner!$B$6:$B$505,"<"&DATE($C$3,10,1))) | M32: =IF($C32="","",SUMIFS(Transaktioner!$E$6:$E$505,Transaktioner!$C$6:$C$505,$C32,Transaktioner!$B$6:$B$505,">="&DATE($C$3,10,1),Transaktioner!$B$6:$B$505,"<"&DATE($C$3,11,1))) | N32: =IF($C32="","",SUMIFS(Transaktioner!$E$6:$E$505,Transaktioner!$C$6:$C$505,$C32,Transaktioner!$B$6:$B$505,">="&DATE($C$3,11,1),Transaktioner!$B$6:$B$505,"<"&DATE($C$3,12,1))) | O32: =IF($C32="","",SUMIFS(Transaktioner!$E$6:$E$505,Transaktioner!$C$6:$C$505,$C32,Transaktioner!$B$6:$B$505,">="&DATE($C$3,12,1),Transaktioner!$B$6:$B$505,"<"&DATE($C$3,13,1))) | P32: =IF($C32="","",SUM(D32:O32)) | Q32: =IF($C32="","",Kategorier!$D$28*12) | R32: =IF($C32="","",IF($B32="Inkomst",P32-Q32,Q32-P32)) | S32: =IF(OR($C32="",N(Q32)=0),"",P32/Q32)
